WARNING : Using CLI version 2.13.0 but project's `requirements.txt`
WARNING : is configured to use 1.5.2. Consider either installing
WARNING : CLI version 1.5.2 or running `pretext update`
WARNING : to update `requirements.txt` and other managed files to match 2.13.0.
INFO    : Now preparing local server to preview your project directory `/workspaces/MSOE-Calculus`.
INFO    :   (Reminder: use `pretext deploy` to deploy your built project to a public
INFO    :   GitHub Pages site that can be shared with readers who cannot access your
INFO    :   personal computer.)
INFO    : 
INFO    : starting server ...
INFO    : Running in a codespace, so using a subprocess server.
INFO    : Starting the server
INFO    : There are 10 or more servers on file. Cleaning up ...
INFO    : Terminating 16019
INFO    : Terminate failed for 16019.
ERROR   : process PID not found (pid=16019)
Traceback (most recent call last):
  File "/home/vscode/.local/lib/python3.13/site-packages/psutil/_pslinux.py", line 1716, in wrapper
    return fun(self, *args, **kwargs)
  File "/home/vscode/.local/lib/python3.13/site-packages/psutil/_common.py", line 508, in wrapper
    raise raise_from(err, None)
          ~~~~~~~~~~^^^^^^^^^^^
  File "<string>", line 3, in raise_from
  File "/home/vscode/.local/lib/python3.13/site-packages/psutil/_common.py", line 506, in wrapper
    return fun(self)
  File "/home/vscode/.local/lib/python3.13/site-packages/psutil/_pslinux.py", line 1784, in _parse_stat_file
    data = bcat("%s/%s/stat" % (self._procfs_path, self.pid))
  File "/home/vscode/.local/lib/python3.13/site-packages/psutil/_common.py", line 851, in bcat
    return cat(fname, fallback=fallback, _open=open_binary)
  File "/home/vscode/.local/lib/python3.13/site-packages/psutil/_common.py", line 839, in cat
    with _open(fname) as f:
         ~~~~~^^^^^^^
  File "/home/vscode/.local/lib/python3.13/site-packages/psutil/_common.py", line 799, in open_binary
    return open(fname, "rb", buffering=FILE_READ_BUFFER_SIZE)
FileNotFoundError: [Errno 2] No such file or directory: '/proc/16019/stat'

During handling of the above exception, another exception occurred:

Traceback (most recent call last):
  File "/home/vscode/.local/lib/python3.13/site-packages/psutil/__init__.py", line 355, in _init
    self._ident = self._get_ident()
                  ~~~~~~~~~~~~~~~^^
  File "/home/vscode/.local/lib/python3.13/site-packages/psutil/__init__.py", line 396, in _get_ident
    return (self.pid, self.create_time())
                      ~~~~~~~~~~~~~~~~^^
  File "/home/vscode/.local/lib/python3.13/site-packages/psutil/__init__.py", line 778, in create_time
    self._create_time = self._proc.create_time()
                        ~~~~~~~~~~~~~~~~~~~~~~^^
  File "/home/vscode/.local/lib/python3.13/site-packages/psutil/_pslinux.py", line 1716, in wrapper
    return fun(self, *args, **kwargs)
  File "/home/vscode/.local/lib/python3.13/site-packages/psutil/_pslinux.py", line 1957, in create_time
    ctime = float(self._parse_stat_file()['create_time'])
                  ~~~~~~~~~~~~~~~~~~~~~^^
  File "/home/vscode/.local/lib/python3.13/site-packages/psutil/_pslinux.py", line 1730, in wrapper
    raise NoSuchProcess(self.pid, self._name)
psutil.NoSuchProcess: process no longer exists (pid=16019)

During handling of the above exception, another exception occurred:

Traceback (most recent call last):
  File "/home/vscode/.local/lib/python3.13/site-packages/pretext/server.py", line 68, in terminate
    psutil.Process(self.pid).terminate()
    ~~~~~~~~~~~~~~^^^^^^^^^^
  File "/home/vscode/.local/lib/python3.13/site-packages/psutil/__init__.py", line 319, in __init__
    self._init(pid)
    ~~~~~~~~~~^^^^^
  File "/home/vscode/.local/lib/python3.13/site-packages/psutil/__init__.py", line 368, in _init
    raise NoSuchProcess(pid, msg=msg)
psutil.NoSuchProcess: process PID not found (pid=16019)
INFO    : Terminating 1427
INFO    : Terminate failed for 1427.
ERROR   : process PID not found (pid=1427)
Traceback (most recent call last):
  File "/home/vscode/.local/lib/python3.13/site-packages/psutil/_pslinux.py", line 1716, in wrapper
    return fun(self, *args, **kwargs)
  File "/home/vscode/.local/lib/python3.13/site-packages/psutil/_common.py", line 508, in wrapper
    raise raise_from(err, None)
          ~~~~~~~~~~^^^^^^^^^^^
  File "<string>", line 3, in raise_from
  File "/home/vscode/.local/lib/python3.13/site-packages/psutil/_common.py", line 506, in wrapper
    return fun(self)
  File "/home/vscode/.local/lib/python3.13/site-packages/psutil/_pslinux.py", line 1784, in _parse_stat_file
    data = bcat("%s/%s/stat" % (self._procfs_path, self.pid))
  File "/home/vscode/.local/lib/python3.13/site-packages/psutil/_common.py", line 851, in bcat
    return cat(fname, fallback=fallback, _open=open_binary)
  File "/home/vscode/.local/lib/python3.13/site-packages/psutil/_common.py", line 839, in cat
    with _open(fname) as f:
         ~~~~~^^^^^^^
  File "/home/vscode/.local/lib/python3.13/site-packages/psutil/_common.py", line 799, in open_binary
    return open(fname, "rb", buffering=FILE_READ_BUFFER_SIZE)
FileNotFoundError: [Errno 2] No such file or directory: '/proc/1427/stat'

During handling of the above exception, another exception occurred:

Traceback (most recent call last):
  File "/home/vscode/.local/lib/python3.13/site-packages/psutil/__init__.py", line 355, in _init
    self._ident = self._get_ident()
                  ~~~~~~~~~~~~~~~^^
  File "/home/vscode/.local/lib/python3.13/site-packages/psutil/__init__.py", line 396, in _get_ident
    return (self.pid, self.create_time())
                      ~~~~~~~~~~~~~~~~^^
  File "/home/vscode/.local/lib/python3.13/site-packages/psutil/__init__.py", line 778, in create_time
    self._create_time = self._proc.create_time()
                        ~~~~~~~~~~~~~~~~~~~~~~^^
  File "/home/vscode/.local/lib/python3.13/site-packages/psutil/_pslinux.py", line 1716, in wrapper
    return fun(self, *args, **kwargs)
  File "/home/vscode/.local/lib/python3.13/site-packages/psutil/_pslinux.py", line 1957, in create_time
    ctime = float(self._parse_stat_file()['create_time'])
                  ~~~~~~~~~~~~~~~~~~~~~^^
  File "/home/vscode/.local/lib/python3.13/site-packages/psutil/_pslinux.py", line 1730, in wrapper
    raise NoSuchProcess(self.pid, self._name)
psutil.NoSuchProcess: process no longer exists (pid=1427)

During handling of the above exception, another exception occurred:

Traceback (most recent call last):
  File "/home/vscode/.local/lib/python3.13/site-packages/pretext/server.py", line 68, in terminate
    psutil.Process(self.pid).terminate()
    ~~~~~~~~~~~~~~^^^^^^^^^^
  File "/home/vscode/.local/lib/python3.13/site-packages/psutil/__init__.py", line 319, in __init__
    self._init(pid)
    ~~~~~~~~~~^^^^^
  File "/home/vscode/.local/lib/python3.13/site-packages/psutil/__init__.py", line 368, in _init
    raise NoSuchProcess(pid, msg=msg)
psutil.NoSuchProcess: process PID not found (pid=1427)
INFO    : Terminating 2675
INFO    : Terminate failed for 2675.
ERROR   : process PID not found (pid=2675)
Traceback (most recent call last):
  File "/home/vscode/.local/lib/python3.13/site-packages/psutil/_pslinux.py", line 1716, in wrapper
    return fun(self, *args, **kwargs)
  File "/home/vscode/.local/lib/python3.13/site-packages/psutil/_common.py", line 508, in wrapper
    raise raise_from(err, None)
          ~~~~~~~~~~^^^^^^^^^^^
  File "<string>", line 3, in raise_from
  File "/home/vscode/.local/lib/python3.13/site-packages/psutil/_common.py", line 506, in wrapper
    return fun(self)
  File "/home/vscode/.local/lib/python3.13/site-packages/psutil/_pslinux.py", line 1784, in _parse_stat_file
    data = bcat("%s/%s/stat" % (self._procfs_path, self.pid))
  File "/home/vscode/.local/lib/python3.13/site-packages/psutil/_common.py", line 851, in bcat
    return cat(fname, fallback=fallback, _open=open_binary)
  File "/home/vscode/.local/lib/python3.13/site-packages/psutil/_common.py", line 839, in cat
    with _open(fname) as f:
         ~~~~~^^^^^^^
  File "/home/vscode/.local/lib/python3.13/site-packages/psutil/_common.py", line 799, in open_binary
    return open(fname, "rb", buffering=FILE_READ_BUFFER_SIZE)
FileNotFoundError: [Errno 2] No such file or directory: '/proc/2675/stat'

During handling of the above exception, another exception occurred:

Traceback (most recent call last):
  File "/home/vscode/.local/lib/python3.13/site-packages/psutil/__init__.py", line 355, in _init
    self._ident = self._get_ident()
                  ~~~~~~~~~~~~~~~^^
  File "/home/vscode/.local/lib/python3.13/site-packages/psutil/__init__.py", line 396, in _get_ident
    return (self.pid, self.create_time())
                      ~~~~~~~~~~~~~~~~^^
  File "/home/vscode/.local/lib/python3.13/site-packages/psutil/__init__.py", line 778, in create_time
    self._create_time = self._proc.create_time()
                        ~~~~~~~~~~~~~~~~~~~~~~^^
  File "/home/vscode/.local/lib/python3.13/site-packages/psutil/_pslinux.py", line 1716, in wrapper
    return fun(self, *args, **kwargs)
  File "/home/vscode/.local/lib/python3.13/site-packages/psutil/_pslinux.py", line 1957, in create_time
    ctime = float(self._parse_stat_file()['create_time'])
                  ~~~~~~~~~~~~~~~~~~~~~^^
  File "/home/vscode/.local/lib/python3.13/site-packages/psutil/_pslinux.py", line 1730, in wrapper
    raise NoSuchProcess(self.pid, self._name)
psutil.NoSuchProcess: process no longer exists (pid=2675)

During handling of the above exception, another exception occurred:

Traceback (most recent call last):
  File "/home/vscode/.local/lib/python3.13/site-packages/pretext/server.py", line 68, in terminate
    psutil.Process(self.pid).terminate()
    ~~~~~~~~~~~~~~^^^^^^^^^^
  File "/home/vscode/.local/lib/python3.13/site-packages/psutil/__init__.py", line 319, in __init__
    self._init(pid)
    ~~~~~~~~~~^^^^^
  File "/home/vscode/.local/lib/python3.13/site-packages/psutil/__init__.py", line 368, in _init
    raise NoSuchProcess(pid, msg=msg)
psutil.NoSuchProcess: process PID not found (pid=2675)
INFO    : Terminating 4961
INFO    : Terminate failed for 4961.
ERROR   : process PID not found (pid=4961)
Traceback (most recent call last):
  File "/home/vscode/.local/lib/python3.13/site-packages/psutil/_pslinux.py", line 1716, in wrapper
    return fun(self, *args, **kwargs)
  File "/home/vscode/.local/lib/python3.13/site-packages/psutil/_common.py", line 508, in wrapper
    raise raise_from(err, None)
          ~~~~~~~~~~^^^^^^^^^^^
  File "<string>", line 3, in raise_from
  File "/home/vscode/.local/lib/python3.13/site-packages/psutil/_common.py", line 506, in wrapper
    return fun(self)
  File "/home/vscode/.local/lib/python3.13/site-packages/psutil/_pslinux.py", line 1784, in _parse_stat_file
    data = bcat("%s/%s/stat" % (self._procfs_path, self.pid))
  File "/home/vscode/.local/lib/python3.13/site-packages/psutil/_common.py", line 851, in bcat
    return cat(fname, fallback=fallback, _open=open_binary)
  File "/home/vscode/.local/lib/python3.13/site-packages/psutil/_common.py", line 839, in cat
    with _open(fname) as f:
         ~~~~~^^^^^^^
  File "/home/vscode/.local/lib/python3.13/site-packages/psutil/_common.py", line 799, in open_binary
    return open(fname, "rb", buffering=FILE_READ_BUFFER_SIZE)
FileNotFoundError: [Errno 2] No such file or directory: '/proc/4961/stat'

During handling of the above exception, another exception occurred:

Traceback (most recent call last):
  File "/home/vscode/.local/lib/python3.13/site-packages/psutil/__init__.py", line 355, in _init
    self._ident = self._get_ident()
                  ~~~~~~~~~~~~~~~^^
  File "/home/vscode/.local/lib/python3.13/site-packages/psutil/__init__.py", line 396, in _get_ident
    return (self.pid, self.create_time())
                      ~~~~~~~~~~~~~~~~^^
  File "/home/vscode/.local/lib/python3.13/site-packages/psutil/__init__.py", line 778, in create_time
    self._create_time = self._proc.create_time()
                        ~~~~~~~~~~~~~~~~~~~~~~^^
  File "/home/vscode/.local/lib/python3.13/site-packages/psutil/_pslinux.py", line 1716, in wrapper
    return fun(self, *args, **kwargs)
  File "/home/vscode/.local/lib/python3.13/site-packages/psutil/_pslinux.py", line 1957, in create_time
    ctime = float(self._parse_stat_file()['create_time'])
                  ~~~~~~~~~~~~~~~~~~~~~^^
  File "/home/vscode/.local/lib/python3.13/site-packages/psutil/_pslinux.py", line 1730, in wrapper
    raise NoSuchProcess(self.pid, self._name)
psutil.NoSuchProcess: process no longer exists (pid=4961)

During handling of the above exception, another exception occurred:

Traceback (most recent call last):
  File "/home/vscode/.local/lib/python3.13/site-packages/pretext/server.py", line 68, in terminate
    psutil.Process(self.pid).terminate()
    ~~~~~~~~~~~~~~^^^^^^^^^^
  File "/home/vscode/.local/lib/python3.13/site-packages/psutil/__init__.py", line 319, in __init__
    self._init(pid)
    ~~~~~~~~~~^^^^^
  File "/home/vscode/.local/lib/python3.13/site-packages/psutil/__init__.py", line 368, in _init
    raise NoSuchProcess(pid, msg=msg)
psutil.NoSuchProcess: process PID not found (pid=4961)
INFO    : Terminating 5945
INFO    : Terminate failed for 5945.
ERROR   : process PID not found (pid=5945)
Traceback (most recent call last):
  File "/home/vscode/.local/lib/python3.13/site-packages/psutil/_pslinux.py", line 1716, in wrapper
    return fun(self, *args, **kwargs)
  File "/home/vscode/.local/lib/python3.13/site-packages/psutil/_common.py", line 508, in wrapper
    raise raise_from(err, None)
          ~~~~~~~~~~^^^^^^^^^^^
  File "<string>", line 3, in raise_from
  File "/home/vscode/.local/lib/python3.13/site-packages/psutil/_common.py", line 506, in wrapper
    return fun(self)
  File "/home/vscode/.local/lib/python3.13/site-packages/psutil/_pslinux.py", line 1784, in _parse_stat_file
    data = bcat("%s/%s/stat" % (self._procfs_path, self.pid))
  File "/home/vscode/.local/lib/python3.13/site-packages/psutil/_common.py", line 851, in bcat
    return cat(fname, fallback=fallback, _open=open_binary)
  File "/home/vscode/.local/lib/python3.13/site-packages/psutil/_common.py", line 839, in cat
    with _open(fname) as f:
         ~~~~~^^^^^^^
  File "/home/vscode/.local/lib/python3.13/site-packages/psutil/_common.py", line 799, in open_binary
    return open(fname, "rb", buffering=FILE_READ_BUFFER_SIZE)
FileNotFoundError: [Errno 2] No such file or directory: '/proc/5945/stat'

During handling of the above exception, another exception occurred:

Traceback (most recent call last):
  File "/home/vscode/.local/lib/python3.13/site-packages/psutil/__init__.py", line 355, in _init
    self._ident = self._get_ident()
                  ~~~~~~~~~~~~~~~^^
  File "/home/vscode/.local/lib/python3.13/site-packages/psutil/__init__.py", line 396, in _get_ident
    return (self.pid, self.create_time())
                      ~~~~~~~~~~~~~~~~^^
  File "/home/vscode/.local/lib/python3.13/site-packages/psutil/__init__.py", line 778, in create_time
    self._create_time = self._proc.create_time()
                        ~~~~~~~~~~~~~~~~~~~~~~^^
  File "/home/vscode/.local/lib/python3.13/site-packages/psutil/_pslinux.py", line 1716, in wrapper
    return fun(self, *args, **kwargs)
  File "/home/vscode/.local/lib/python3.13/site-packages/psutil/_pslinux.py", line 1957, in create_time
    ctime = float(self._parse_stat_file()['create_time'])
                  ~~~~~~~~~~~~~~~~~~~~~^^
  File "/home/vscode/.local/lib/python3.13/site-packages/psutil/_pslinux.py", line 1730, in wrapper
    raise NoSuchProcess(self.pid, self._name)
psutil.NoSuchProcess: process no longer exists (pid=5945)

During handling of the above exception, another exception occurred:

Traceback (most recent call last):
  File "/home/vscode/.local/lib/python3.13/site-packages/pretext/server.py", line 68, in terminate
    psutil.Process(self.pid).terminate()
    ~~~~~~~~~~~~~~^^^^^^^^^^
  File "/home/vscode/.local/lib/python3.13/site-packages/psutil/__init__.py", line 319, in __init__
    self._init(pid)
    ~~~~~~~~~~^^^^^
  File "/home/vscode/.local/lib/python3.13/site-packages/psutil/__init__.py", line 368, in _init
    raise NoSuchProcess(pid, msg=msg)
psutil.NoSuchProcess: process PID not found (pid=5945)
INFO    : Terminating 7418
INFO    : Terminate failed for 7418.
ERROR   : process PID not found (pid=7418)
Traceback (most recent call last):
  File "/home/vscode/.local/lib/python3.13/site-packages/psutil/_pslinux.py", line 1716, in wrapper
    return fun(self, *args, **kwargs)
  File "/home/vscode/.local/lib/python3.13/site-packages/psutil/_common.py", line 508, in wrapper
    raise raise_from(err, None)
          ~~~~~~~~~~^^^^^^^^^^^
  File "<string>", line 3, in raise_from
  File "/home/vscode/.local/lib/python3.13/site-packages/psutil/_common.py", line 506, in wrapper
    return fun(self)
  File "/home/vscode/.local/lib/python3.13/site-packages/psutil/_pslinux.py", line 1784, in _parse_stat_file
    data = bcat("%s/%s/stat" % (self._procfs_path, self.pid))
  File "/home/vscode/.local/lib/python3.13/site-packages/psutil/_common.py", line 851, in bcat
    return cat(fname, fallback=fallback, _open=open_binary)
  File "/home/vscode/.local/lib/python3.13/site-packages/psutil/_common.py", line 839, in cat
    with _open(fname) as f:
         ~~~~~^^^^^^^
  File "/home/vscode/.local/lib/python3.13/site-packages/psutil/_common.py", line 799, in open_binary
    return open(fname, "rb", buffering=FILE_READ_BUFFER_SIZE)
FileNotFoundError: [Errno 2] No such file or directory: '/proc/7418/stat'

During handling of the above exception, another exception occurred:

Traceback (most recent call last):
  File "/home/vscode/.local/lib/python3.13/site-packages/psutil/__init__.py", line 355, in _init
    self._ident = self._get_ident()
                  ~~~~~~~~~~~~~~~^^
  File "/home/vscode/.local/lib/python3.13/site-packages/psutil/__init__.py", line 396, in _get_ident
    return (self.pid, self.create_time())
                      ~~~~~~~~~~~~~~~~^^
  File "/home/vscode/.local/lib/python3.13/site-packages/psutil/__init__.py", line 778, in create_time
    self._create_time = self._proc.create_time()
                        ~~~~~~~~~~~~~~~~~~~~~~^^
  File "/home/vscode/.local/lib/python3.13/site-packages/psutil/_pslinux.py", line 1716, in wrapper
    return fun(self, *args, **kwargs)
  File "/home/vscode/.local/lib/python3.13/site-packages/psutil/_pslinux.py", line 1957, in create_time
    ctime = float(self._parse_stat_file()['create_time'])
                  ~~~~~~~~~~~~~~~~~~~~~^^
  File "/home/vscode/.local/lib/python3.13/site-packages/psutil/_pslinux.py", line 1730, in wrapper
    raise NoSuchProcess(self.pid, self._name)
psutil.NoSuchProcess: process no longer exists (pid=7418)

During handling of the above exception, another exception occurred:

Traceback (most recent call last):
  File "/home/vscode/.local/lib/python3.13/site-packages/pretext/server.py", line 68, in terminate
    psutil.Process(self.pid).terminate()
    ~~~~~~~~~~~~~~^^^^^^^^^^
  File "/home/vscode/.local/lib/python3.13/site-packages/psutil/__init__.py", line 319, in __init__
    self._init(pid)
    ~~~~~~~~~~^^^^^
  File "/home/vscode/.local/lib/python3.13/site-packages/psutil/__init__.py", line 368, in _init
    raise NoSuchProcess(pid, msg=msg)
psutil.NoSuchProcess: process PID not found (pid=7418)
INFO    : Terminating 9141
INFO    : Terminate failed for 9141.
ERROR   : process PID not found (pid=9141)
Traceback (most recent call last):
  File "/home/vscode/.local/lib/python3.13/site-packages/psutil/_pslinux.py", line 1716, in wrapper
    return fun(self, *args, **kwargs)
  File "/home/vscode/.local/lib/python3.13/site-packages/psutil/_common.py", line 508, in wrapper
    raise raise_from(err, None)
          ~~~~~~~~~~^^^^^^^^^^^
  File "<string>", line 3, in raise_from
  File "/home/vscode/.local/lib/python3.13/site-packages/psutil/_common.py", line 506, in wrapper
    return fun(self)
  File "/home/vscode/.local/lib/python3.13/site-packages/psutil/_pslinux.py", line 1784, in _parse_stat_file
    data = bcat("%s/%s/stat" % (self._procfs_path, self.pid))
  File "/home/vscode/.local/lib/python3.13/site-packages/psutil/_common.py", line 851, in bcat
    return cat(fname, fallback=fallback, _open=open_binary)
  File "/home/vscode/.local/lib/python3.13/site-packages/psutil/_common.py", line 839, in cat
    with _open(fname) as f:
         ~~~~~^^^^^^^
  File "/home/vscode/.local/lib/python3.13/site-packages/psutil/_common.py", line 799, in open_binary
    return open(fname, "rb", buffering=FILE_READ_BUFFER_SIZE)
FileNotFoundError: [Errno 2] No such file or directory: '/proc/9141/stat'

During handling of the above exception, another exception occurred:

Traceback (most recent call last):
  File "/home/vscode/.local/lib/python3.13/site-packages/psutil/__init__.py", line 355, in _init
    self._ident = self._get_ident()
                  ~~~~~~~~~~~~~~~^^
  File "/home/vscode/.local/lib/python3.13/site-packages/psutil/__init__.py", line 396, in _get_ident
    return (self.pid, self.create_time())
                      ~~~~~~~~~~~~~~~~^^
  File "/home/vscode/.local/lib/python3.13/site-packages/psutil/__init__.py", line 778, in create_time
    self._create_time = self._proc.create_time()
                        ~~~~~~~~~~~~~~~~~~~~~~^^
  File "/home/vscode/.local/lib/python3.13/site-packages/psutil/_pslinux.py", line 1716, in wrapper
    return fun(self, *args, **kwargs)
  File "/home/vscode/.local/lib/python3.13/site-packages/psutil/_pslinux.py", line 1957, in create_time
    ctime = float(self._parse_stat_file()['create_time'])
                  ~~~~~~~~~~~~~~~~~~~~~^^
  File "/home/vscode/.local/lib/python3.13/site-packages/psutil/_pslinux.py", line 1730, in wrapper
    raise NoSuchProcess(self.pid, self._name)
psutil.NoSuchProcess: process no longer exists (pid=9141)

During handling of the above exception, another exception occurred:

Traceback (most recent call last):
  File "/home/vscode/.local/lib/python3.13/site-packages/pretext/server.py", line 68, in terminate
    psutil.Process(self.pid).terminate()
    ~~~~~~~~~~~~~~^^^^^^^^^^
  File "/home/vscode/.local/lib/python3.13/site-packages/psutil/__init__.py", line 319, in __init__
    self._init(pid)
    ~~~~~~~~~~^^^^^
  File "/home/vscode/.local/lib/python3.13/site-packages/psutil/__init__.py", line 368, in _init
    raise NoSuchProcess(pid, msg=msg)
psutil.NoSuchProcess: process PID not found (pid=9141)
INFO    : Terminating 11432
INFO    : Terminate failed for 11432.
ERROR   : process PID not found (pid=11432)
Traceback (most recent call last):
  File "/home/vscode/.local/lib/python3.13/site-packages/psutil/_pslinux.py", line 1716, in wrapper
    return fun(self, *args, **kwargs)
  File "/home/vscode/.local/lib/python3.13/site-packages/psutil/_common.py", line 508, in wrapper
    raise raise_from(err, None)
          ~~~~~~~~~~^^^^^^^^^^^
  File "<string>", line 3, in raise_from
  File "/home/vscode/.local/lib/python3.13/site-packages/psutil/_common.py", line 506, in wrapper
    return fun(self)
  File "/home/vscode/.local/lib/python3.13/site-packages/psutil/_pslinux.py", line 1784, in _parse_stat_file
    data = bcat("%s/%s/stat" % (self._procfs_path, self.pid))
  File "/home/vscode/.local/lib/python3.13/site-packages/psutil/_common.py", line 851, in bcat
    return cat(fname, fallback=fallback, _open=open_binary)
  File "/home/vscode/.local/lib/python3.13/site-packages/psutil/_common.py", line 839, in cat
    with _open(fname) as f:
         ~~~~~^^^^^^^
  File "/home/vscode/.local/lib/python3.13/site-packages/psutil/_common.py", line 799, in open_binary
    return open(fname, "rb", buffering=FILE_READ_BUFFER_SIZE)
FileNotFoundError: [Errno 2] No such file or directory: '/proc/11432/stat'

During handling of the above exception, another exception occurred:

Traceback (most recent call last):
  File "/home/vscode/.local/lib/python3.13/site-packages/psutil/__init__.py", line 355, in _init
    self._ident = self._get_ident()
                  ~~~~~~~~~~~~~~~^^
  File "/home/vscode/.local/lib/python3.13/site-packages/psutil/__init__.py", line 396, in _get_ident
    return (self.pid, self.create_time())
                      ~~~~~~~~~~~~~~~~^^
  File "/home/vscode/.local/lib/python3.13/site-packages/psutil/__init__.py", line 778, in create_time
    self._create_time = self._proc.create_time()
                        ~~~~~~~~~~~~~~~~~~~~~~^^
  File "/home/vscode/.local/lib/python3.13/site-packages/psutil/_pslinux.py", line 1716, in wrapper
    return fun(self, *args, **kwargs)
  File "/home/vscode/.local/lib/python3.13/site-packages/psutil/_pslinux.py", line 1957, in create_time
    ctime = float(self._parse_stat_file()['create_time'])
                  ~~~~~~~~~~~~~~~~~~~~~^^
  File "/home/vscode/.local/lib/python3.13/site-packages/psutil/_pslinux.py", line 1730, in wrapper
    raise NoSuchProcess(self.pid, self._name)
psutil.NoSuchProcess: process no longer exists (pid=11432)

During handling of the above exception, another exception occurred:

Traceback (most recent call last):
  File "/home/vscode/.local/lib/python3.13/site-packages/pretext/server.py", line 68, in terminate
    psutil.Process(self.pid).terminate()
    ~~~~~~~~~~~~~~^^^^^^^^^^
  File "/home/vscode/.local/lib/python3.13/site-packages/psutil/__init__.py", line 319, in __init__
    self._init(pid)
    ~~~~~~~~~~^^^^^
  File "/home/vscode/.local/lib/python3.13/site-packages/psutil/__init__.py", line 368, in _init
    raise NoSuchProcess(pid, msg=msg)
psutil.NoSuchProcess: process PID not found (pid=11432)
INFO    : Terminating 1241
INFO    : Terminate failed for 1241.
ERROR   : process PID not found (pid=1241)
Traceback (most recent call last):
  File "/home/vscode/.local/lib/python3.13/site-packages/psutil/_pslinux.py", line 1716, in wrapper
    return fun(self, *args, **kwargs)
  File "/home/vscode/.local/lib/python3.13/site-packages/psutil/_common.py", line 508, in wrapper
    raise raise_from(err, None)
          ~~~~~~~~~~^^^^^^^^^^^
  File "<string>", line 3, in raise_from
  File "/home/vscode/.local/lib/python3.13/site-packages/psutil/_common.py", line 506, in wrapper
    return fun(self)
  File "/home/vscode/.local/lib/python3.13/site-packages/psutil/_pslinux.py", line 1784, in _parse_stat_file
    data = bcat("%s/%s/stat" % (self._procfs_path, self.pid))
  File "/home/vscode/.local/lib/python3.13/site-packages/psutil/_common.py", line 851, in bcat
    return cat(fname, fallback=fallback, _open=open_binary)
  File "/home/vscode/.local/lib/python3.13/site-packages/psutil/_common.py", line 839, in cat
    with _open(fname) as f:
         ~~~~~^^^^^^^
  File "/home/vscode/.local/lib/python3.13/site-packages/psutil/_common.py", line 799, in open_binary
    return open(fname, "rb", buffering=FILE_READ_BUFFER_SIZE)
FileNotFoundError: [Errno 2] No such file or directory: '/proc/1241/stat'

During handling of the above exception, another exception occurred:

Traceback (most recent call last):
  File "/home/vscode/.local/lib/python3.13/site-packages/psutil/__init__.py", line 355, in _init
    self._ident = self._get_ident()
                  ~~~~~~~~~~~~~~~^^
  File "/home/vscode/.local/lib/python3.13/site-packages/psutil/__init__.py", line 396, in _get_ident
    return (self.pid, self.create_time())
                      ~~~~~~~~~~~~~~~~^^
  File "/home/vscode/.local/lib/python3.13/site-packages/psutil/__init__.py", line 778, in create_time
    self._create_time = self._proc.create_time()
                        ~~~~~~~~~~~~~~~~~~~~~~^^
  File "/home/vscode/.local/lib/python3.13/site-packages/psutil/_pslinux.py", line 1716, in wrapper
    return fun(self, *args, **kwargs)
  File "/home/vscode/.local/lib/python3.13/site-packages/psutil/_pslinux.py", line 1957, in create_time
    ctime = float(self._parse_stat_file()['create_time'])
                  ~~~~~~~~~~~~~~~~~~~~~^^
  File "/home/vscode/.local/lib/python3.13/site-packages/psutil/_pslinux.py", line 1730, in wrapper
    raise NoSuchProcess(self.pid, self._name)
psutil.NoSuchProcess: process no longer exists (pid=1241)

During handling of the above exception, another exception occurred:

Traceback (most recent call last):
  File "/home/vscode/.local/lib/python3.13/site-packages/pretext/server.py", line 68, in terminate
    psutil.Process(self.pid).terminate()
    ~~~~~~~~~~~~~~^^^^^^^^^^
  File "/home/vscode/.local/lib/python3.13/site-packages/psutil/__init__.py", line 319, in __init__
    self._init(pid)
    ~~~~~~~~~~^^^^^
  File "/home/vscode/.local/lib/python3.13/site-packages/psutil/__init__.py", line 368, in _init
    raise NoSuchProcess(pid, msg=msg)
psutil.NoSuchProcess: process PID not found (pid=1241)
INFO    : Found server at localhost:8128
INFO    : Added server entry 8b1c3b4564 1108 8128 localhost

INFO    : Server will soon be available at https://refactored-carnival-xgvp9p479jjf6rww-8128.app.github.dev
INFO    : Opening browser for target `web` at https://refactored-carnival-xgvp9p479jjf6rww-8128.app.github.dev/output/web
INFO    : 
----------------------------------------------------
INFO    : While running pretext, the following errors occurred:

INFO    : (see log messages above or in the 'logs' folder for more information)
INFO    : ----------------------------------------------------
